Workbook
Name TABATUAL: [1]Plan2!$A$1:$B$1285

Sheet COMMERCIAL INVOICE
A1: #VALUE! | C1: COMMERCIAL INVOICE | Q1: C-129/2026
A4: Exporter and Manufacturer | Q4: Date: | R4: 06/24/2026
A5: LIVE ROUPAS ESPORTIVAS LTDA | Q5: Place of Loading: | R5: Place of Delivery:
A6: RUA MANOEL FRANCISCO DA COSTA, 1600, PREDIO 01, PISO 02 | Q6: Jaraguá do Sul/BR | R6: Miami/USA
A7: VIEIRA - JARAGUÁ DO SUL - SANTA CATARINA - BRASIL | Q7: Total Net Weight: | R7: Total Gross Weight:
A8: CNPJ: 05.108.435/0001-78 | Q8: 34.32 | R8: 38.4
A9: TEL.: 55 47 2106 7400 | Q9: Country of Origin: | R9: Volumes:
Q10: Brazil | R10: 3 Cartoon Boxes
A11: BUYER
A12: CUSTOMER: | D12: LIVE! CLOTHING LLC - EIN 371775533
A13: CONTACT PERSON: | D13: CINTIA NETTO
A14: ADDRESS: | D14: 723 LINCOLN ROAD - 33139
A15: CITY: | D15: MIAMI - FL
A16: COUNTRY: | D16: UNITED STATES OF AMERICA
A17: EMAIL: | D17: ecommerce@liveclothing.com
A18: PHONE: | D18: +1 (305) 537-4910 / (561) 543-5998
A19: SHIP TO
A20: CONSIGNEE: | D20: LIVE! CLOTHING LLC - EIN 371775533
A21: CONTACT PERSON: | D21: CINTIA NETTO
A22: ADDRESS: | D22: 723 LINCOLN ROAD - 33139
A23: CITY: | D23: MIAMI - FL
A24: COUNTRY: | D24: UNITED STATES OF AMERICA
A25: EMAIL: | D25: ecommerce@liveclothing.com
A26: PHONE: | D26: +1 (305) 537-4910 / (561) 543-5998
A27: INCOTERM: | D27: CIP
A28: TERMS OF PAYMENT: | D28: 365 DAYS AFTER INVOICE DATE
A29: REFERENCE | B29: NCM | C29: COLOR | D29: PRODUCT MATERIALS | E29: GENERAL DESCRIPTION | F29: COMPOSITION | J29: DESCRIPTION | K29: XS | L29: S | M29: M | N29: L | O29: XL | P29: UNIT | Q29: UNIT PRICE USD | R29: TOTAL AMOUNT USD
A30: 46586 | B30: 6114.30.30.30 | C30: 00RX80 | D30: Of man-made fibres | E30: Activewear Clothes, Knit. | F30: =VLOOKUP(A30,'[2]Todas Coleções'!$A:$E,5,FALSE) -> 92% PA / 8% EL | G30: =_xlfn.IMAGE(H30) -> #VALUE! | H30: =VLOOKUP(I30,[3]exportarImagens_10_07_2026_09_4!$C:$D,2,FALSE) -> https://imagens.liveoficial.com.br/product/80x120/506971_46586_00RX80_1.jpg | I30: =A30&C30 -> 4658600RX80 | J30: Melt Square Bra | M30: 3 | N30: 2 | P30: =SUM(K30:O30) -> 5 | Q30: =VLOOKUP(A30,'SOLVER NOVO'!A:E,5,FALSE) -> 8.6141795 | R30: =Q30*P30 -> 43.070897
A31: 46588 | B31: 6104.63.10.20 | C31: 00RX80 | D31: Of synthetic fibres | E31: Activewear Clothes, Knit. | F31: =VLOOKUP(A31,'[2]Todas Coleções'!$A:$E,5,FALSE) -> 92% PA / 8% EL | G31: =_xlfn.IMAGE(H31) -> #VALUE! | H31: =VLOOKUP(I31,[3]exportarImagens_10_07_2026_09_4!$C:$D,2,FALSE) -> https://imagens.liveoficial.com.br/product/80x120/506979_46588_00RX80_1.jpg | I31: =A31&C31 -> 4658800RX80 | J31: Melt Square Full Legging | M31: 2 | P31: =SUM(K31:O31) -> 2 | Q31: =VLOOKUP(A31,'SOLVER NOVO'!A:E,5,FALSE) -> 10.493706 | R31: =Q31*P31 -> 20.987412
A32: 46589 | B32: 6104.63.10.20 | C32: 00RX80 | D32: Of synthetic fibres | E32: Activewear Clothes, Knit. | F32: =VLOOKUP(A32,'[2]Todas Coleções'!$A:$E,5,FALSE) -> 92% PA / 8% EL | G32: =_xlfn.IMAGE(H32) -> #VALUE! | H32: =VLOOKUP(I32,[3]exportarImagens_10_07_2026_09_4!$C:$D,2,FALSE) -> https://imagens.liveoficial.com.br/product/80x120/501029_46589_00RX80_1.jpg | I32: =A32&C32 -> 4658900RX80 | J32: Square Melt Ballerina Pants | L32: 2 | P32: =SUM(K32:O32) -> 2 | Q32: =VLOOKUP(A32,'SOLVER NOVO'!A:E,5,FALSE) -> 9.0113994 | R32: =Q32*P32 -> 18.022799
A33: 46591 | B33: 6104.63.10.20 | C33: 00RX80 | D33: Of synthetic fibres | E33: Activewear Clothes, Knit. | F33: =VLOOKUP(A33,'[2]Todas Coleções'!$A:$E,5,FALSE) -> 97% PA / 3% EL | G33: =_xlfn.IMAGE(H33) -> #VALUE! | H33: =VLOOKUP(I33,[3]exportarImagens_10_07_2026_09_4!$C:$D,2,FALSE) -> https://imagens.liveoficial.com.br/product/80x120/501021_46591_00RX80_1.jpg | I33: =A33&C33 -> 4659100RX80 | J33: Seamless Mesh Full Legging | L33: 2 | M33: 2 | P33: =SUM(K33:O33) -> 4 | Q33: =VLOOKUP(A33,'SOLVER NOVO'!A:E,5,FALSE) -> 9.6712217 | R33: =Q33*P33 -> 38.684887
A34: 46592 | B34: 6114.30.30.30 | C34: 00RX80 | D34: Of man-made fibres | E34: Activewear Clothes, Knit. | F34: =VLOOKUP(A34,'[2]Todas Coleções'!$A:$E,5,FALSE) -> 97% PA / 3% EL | G34: =_xlfn.IMAGE(H34) -> #VALUE! | H34: =VLOOKUP(I34,[3]exportarImagens_10_07_2026_09_4!$C:$D,2,FALSE) -> https://imagens.liveoficial.com.br/product/80x120/500982_46592_00RX80_1.jpg | I34: =A34&C34 -> 4659200RX80 | J34: Seamless Knit Short Bodysuit | K34: 1 | L34: 3 | P34: =SUM(K34:O34) -> 4 | Q34: =VLOOKUP(A34,'SOLVER NOVO'!A:E,5,FALSE) -> 9.764121 | R34: =Q34*P34 -> 39.056484
A35: P0063 | B35: 6114.30.30.30 | C35: 00BC14 | D35: Of man-made fibres | E35: Activewear Clothes, Knit. | F35: =VLOOKUP(A35,'[2]Todas Coleções'!$A:$E,5,FALSE) -> 87% PA / 13% EL | G35: =_xlfn.IMAGE(H35) -> #VALUE! | H35: =VLOOKUP(I35,[3]exportarImagens_10_07_2026_09_4!$C:$D,2,FALSE) -> https://imagens.liveoficial.com.br/product/80x120/515440_P0063_00BC14_2.jpg | I35: =A35&C35 -> P006300BC14 | J35: LIVE Curve Bra | K35: 1 | L35: 3 | O35: 1 | P35: =SUM(K35:O35) -> 5 | Q35: =VLOOKUP(A35,'SOLVER NOVO'!A:E,5,FALSE) -> 11.37848 | R35: =Q35*P35 -> 56.8924
A36: P1153 | B36: 6109.90.80.10 | C36: 00BC14 | D36: Of other textile materials | E36: Activewear Clothes, Knit. | F36: =VLOOKUP(A36,'[2]Todas Coleções'!$A:$E,5,FALSE) -> 100% PA | G36: =_xlfn.IMAGE(H36) -> #VALUE! | H36: =VLOOKUP(I36,[3]exportarImagens_10_07_2026_09_4!$C:$D,2,FALSE) -> https://imagens.liveoficial.com.br/product/80x120/515554_P1153_00BC14_1.jpg | I36: =A36&C36 -> P115300BC14 | J36: LIVE Comfort TShirt | K36: 1 | L36: 3 | M36: 3 | N36: 1 | O36: 1 | P36: =SUM(K36:O36) -> 9 | Q36: =VLOOKUP(A36,'SOLVER NOVO'!A:E,5,FALSE) -> 9.1533296 | R36: =Q36*P36 -> 82.379967
A37: P1153 | B37: 6109.90.80.10 | C37: 00RX80 | D37: Of other textile materials | E37: Activewear Clothes, Knit. | F37: =VLOOKUP(A37,'[2]Todas Coleções'!$A:$E,5,FALSE) -> 100% PA | G37: =_xlfn.IMAGE(H37) -> #VALUE! | H37: =VLOOKUP(I37,[3]exportarImagens_10_07_2026_09_4!$C:$D,2,FALSE) -> https://imagens.liveoficial.com.br/product/80x120/522333_P1153_00RX80_1.jpg | I37: =A37&C37 -> P115300RX80 | J37: LIVE Comfort TShirt | L37: 3 | N37: 2 | P37: =SUM(K37:O37) -> 5 | Q37: =VLOOKUP(A37,'SOLVER NOVO'!A:E,5,FALSE) -> 9.1533296 | R37: =Q37*P37 -> 45.766648
A38: P1153 | B38: 6109.90.80.10 | C38: 0AZ190 | D38: Of other textile materials | E38: Activewear Clothes, Knit. | F38: =VLOOKUP(A38,'[2]Todas Coleções'!$A:$E,5,FALSE) -> 100% PA | G38: =_xlfn.IMAGE(H38) -> #VALUE! | H38: =VLOOKUP(I38,[3]exportarImagens_10_07_2026_09_4!$C:$D,2,FALSE) -> https://imagens.liveoficial.com.br/product/80x120/521961_P1153_0AZ190_2.jpg | I38: =A38&C38 -> P11530AZ190 | J38: LIVE Comfort TShirt | K38: 1 | L38: 2 | N38: 1 | P38: =SUM(K38:O38) -> 4 | Q38: =VLOOKUP(A38,'SOLVER NOVO'!A:E,5,FALSE) -> 9.1533296 | R38: =Q38*P38 -> 36.613319
A39: P1154 | B39: 6106.20.10.10 | C39: 00BC14 | D39: Of man-made fibres | E39: Activewear Clothes, Knit. | F39: =VLOOKUP(A39,'[2]Todas Coleções'!$A:$E,5,FALSE) -> 100% PA | G39: =_xlfn.IMAGE(H39) -> #VALUE! | H39: =VLOOKUP(I39,[3]exportarImagens_10_07_2026_09_4!$C:$D,2,FALSE) -> https://imagens.liveoficial.com.br/product/80x120/515472_P1154_00BC14_2.jpg | I39: =A39&C39 -> P115400BC14 | J39: LIVE Comfort Tank Top | L39: 3 | P39: =SUM(K39:O39) -> 3 | Q39: =VLOOKUP(A39,'SOLVER NOVO'!A:E,5,FALSE) -> 7.817765 | R39: =Q39*P39 -> 23.453295
A40: P1154 | B40: 6106.20.10.10 | C40: 00RX80 | D40: Of man-made fibres | E40: Activewear Clothes, Knit. | F40: =VLOOKUP(A40,'[2]Todas Coleções'!$A:$E,5,FALSE) -> 100% PA | G40: =_xlfn.IMAGE(H40) -> #VALUE! | H40: =VLOOKUP(I40,[3]exportarImagens_10_07_2026_09_4!$C:$D,2,FALSE) -> https://imagens.liveoficial.com.br/product/80x120/508191_P1154_00RX80_2.jpg | I40: =A40&C40 -> P115400RX80 | J40: LIVE Comfort Tank Top | N40: 2 | O40: 1 | P40: =SUM(K40:O40) -> 3 | Q40: =VLOOKUP(A40,'SOLVER NOVO'!A:E,5,FALSE) -> 7.817765 | R40: =Q40*P40 -> 23.453295
A41: P1213 | B41: 6106.20.10.10 | C41: 00BC14 | D41: Of man-made fibres | E41: Activewear Clothes, Knit. | F41: =VLOOKUP(A41,'[2]Todas Coleções'!$A:$E,5,FALSE) -> 100% PA | G41: =_xlfn.IMAGE(H41) -> #VALUE! | H41: =VLOOKUP(I41,[3]exportarImagens_10_07_2026_09_4!$C:$D,2,FALSE) -> https://imagens.liveoficial.com.br/product/80x120/515483_P1213_00BC14_2.jpg | I41: =A41&C41 -> P121300BC14 | J41: LIVE Comfort Crop Tank | L41: 2 | M41: 2 | O41: 1 | P41: =SUM(K41:O41) -> 5 | Q41: =VLOOKUP(A41,'SOLVER NOVO'!A:E,5,FALSE) -> 8.7312149 | R41: =Q41*P41 -> 43.656075
A42: P1213 | B42: 6106.20.10.10 | C42: 00RX80 | D42: Of man-made fibres | E42: Activewear Clothes, Knit. | F42: =VLOOKUP(A42,'[2]Todas Coleções'!$A:$E,5,FALSE) -> 100% PA | G42: =_xlfn.IMAGE(H42) -> #VALUE! | H42: =VLOOKUP(I42,[3]exportarImagens_10_07_2026_09_4!$C:$D,2,FALSE) -> https://imagens.liveoficial.com.br/product/80x120/508194_P1213_00RX80_2.jpg | I42: =A42&C42 -> P121300RX80 | J42: LIVE Comfort Crop Tank | M42: 2 | O42: 1 | P42: =SUM(K42:O42) -> 3 | Q42: =VLOOKUP(A42,'SOLVER NOVO'!A:E,5,FALSE) -> 8.7312149 | R42: =Q42*P42 -> 26.193645
...

Sheet invoice
A1: Order | B1: Reference | C1: N.C.M. | D1: Color | E1: Product Materials | F1: Composition | G1: Description | H1: XS | I1: S | J1: M | K1: L | L1: XL
A2: 2799646 | B2: 46586 | C2: 6114.30.30.30 | D2: 00RX80 | E2: Of man-made fibres | F2: BODY: 8% ELASTANE / 92% POLYAMIDE - LINING: 10% ELASTANE / 90% POLYAMIDE | G2: Melt Square Bra | J2: 3 | K2: 2
A3: 2799646 | B3: 46588 | C3: 6104.63.10.20 | D3: 00RX80 | E3: Of synthetic fibres | F3: BODY: 8% ELASTANE / 92% POLYAMIDE - LINING: 10% ELASTANE / 90% POLYAMIDE | G3: Melt Square Full Legging | J3: 2
A4: 2799646 | B4: 46589 | C4: 6104.63.10.20 | D4: 00RX80 | E4: Of synthetic fibres | F4: 8% ELASTANE / 92% POLYAMIDE | G4: Square Melt Ballerina Pants | I4: 2
A5: 2799646 | B5: 46591 | C5: 6104.63.10.20 | D5: 00RX80 | E5: Of synthetic fibres | F5: 3% ELASTANE / 97% POLYAMIDE | G5: Seamless Mesh Full Legging | I5: 2 | J5: 2
A6: 2799646 | B6: 46592 | C6: 6114.30.30.30 | D6: 00RX80 | E6: Of man-made fibres | F6: 3% ELASTANE / 97% POLYAMIDE | G6: Seamless Knit Short Bodysuit | H6: 1 | I6: 3
A7: 2799646 | B7: P0063 | C7: 6114.30.30.30 | D7: 00BC14 | E7: Of man-made fibres | F7: BODY/LINING: 14% ELASTANE / 86% POLYAMIDE / - OUTSIDE / LINING: 14% ELASTANE / 41% POLYESTER / 45% POLYAMIDE / - OUTSIDE/LINING: 13% ELASTANE / 14% ELASTANE / 86% POLYAMIDE / 87% POLYAMIDE / - 13% ELASTANE / 14% ELASTANE / 41% POLYESTER / 45% POLYAMIDE / 87% POLYAMIDE | G7: LIVE Curve Bra | H7: 1 | I7: 3 | L7: 1
A8: 2799646 | B8: P1153 | C8: 6109.90.80.10 | D8: 00BC14 | E8: Of other textile materials | F8: 100% POLYAMIDE | G8: LIVE Comfort TShirt | H8: 1 | I8: 3 | J8: 3 | K8: 1 | L8: 1
A9: 2799646 | B9: P1153 | C9: 6109.90.80.10 | D9: 00RX80 | E9: Of other textile materials | F9: 100% POLYAMIDE | G9: LIVE Comfort TShirt | I9: 3 | K9: 2
A10: 2799646 | B10: P1153 | C10: 6109.90.80.10 | D10: 0AZ190 | E10: Of other textile materials | F10: 100% POLYAMIDE | G10: LIVE Comfort TShirt | H10: 1 | I10: 2 | K10: 1
A11: 2799646 | B11: P1154 | C11: 6106.20.10.10 | D11: 00BC14 | E11: Of man-made fibres | F11: 100% POLYAMIDE | G11: LIVE Comfort Tank Top | I11: 3
A12: 2799646 | B12: P1154 | C12: 6106.20.10.10 | D12: 00RX80 | E12: Of man-made fibres | F12: 100% POLYAMIDE | G12: LIVE Comfort Tank Top | K12: 2 | L12: 1
A13: 2799646 | B13: P1213 | C13: 6106.20.10.10 | D13: 00BC14 | E13: Of man-made fibres | F13: 100% POLYAMIDE | G13: LIVE Comfort Crop Tank | I13: 2 | J13: 2 | L13: 1
A14: 2799646 | B14: P1213 | C14: 6106.20.10.10 | D14: 00RX80 | E14: Of man-made fibres | F14: 100% POLYAMIDE | G14: LIVE Comfort Crop Tank | J14: 2 | L14: 1
A15: 2799646 | B15: P1222 | C15: 6114.30.30.30 | D15: 00BC14 | E15: Of man-made fibres | F15: BODY: 13% ELASTANE / 87% POLYAMIDE / - BODY AND LINING: 13% ELASTANE / 87% POLYAMIDE - LINING: 10% ELASTANE / 90% POLYAMIDE / 92% POLYESTER / - LININIG: 10% ELASTANE / 8% ELASTANE / - OUTSIDE: 13% ELASTANE / 87% POLYAMIDE / - 13% ELASTANE / 14% ELASTANE / 41% POLYESTER / 45% POLYAMIDE / 86% POLYAMIDE / 87% POLYAMIDE | G15: LIVE Move Bra | J15: 3 | K15: 2
A16: 2799646 | B16: P1225 | C16: 6104.63.10.20 | D16: 00RX80 | E16: Of synthetic fibres | F16: BODY: 12% ELASTANE / 88% POLYAMIDE / - 12% ELASTANE / 88% POLYAMIDE | G16: LIVE Icon Neo Short | J16: 3
A17: 2799646 | B17: P1226 | C17: 6104.63.10.20 | D17: 00RX80 | E17: Of synthetic fibres | F17: BODY: 12% ELASTANE / 88% POLYAMIDE / - 12% ELASTANE / 88% POLYAMIDE | G17: LIVE Icon Neo Full Legging | I17: 3 | J17: 2
A18: 2799646 | B18: P1298 | C18: 6114.30.30.30 | D18: 00RX80 | E18: Of man-made fibres | F18: BODY: 12% ELASTANE / 88% POLYAMIDE - LINING: 10% ELASTANE / 90% POLYAMIDE / - OUTSIDE: 12% ELASTANE / 88% POLYAMIDE | G18: LIVE Icon Neo Bra | I18: 3 | J18: 2 | K18: 1
A19: 2799646 | B19: P1434 | C19: 6114.30.30.30 | D19: 00RX80 | E19: Of man-made fibres | F19: BODY AND LINING: 10% ELASTANE / 90% POLYAMIDE / - BODY/LINING: 10% ELASTANE / 7% ELASTANE / 90% POLYAMIDE / 93% POLYAMIDE / - OUTSIDE / LINING: 10% ELASTANE / 44% POLYESTER / 49% POLYAMIDE / 7% ELASTANE / 90% POLYAMIDE / 93% POLYAMIDE / - OUTSIDE/LINING: 10% ELASTANE / 44% POLYESTER / 49% POLYAMIDE / 7% ELASTANE / 90% POLYAMIDE / - 10% ELASTANE / 90% POLYAMIDE | G19: Sense Curve Bra | H19: 1 | I19: 3 | J19: 3 | K19: 2 | L19: 1
A20: 2799646 | B20: P1437 | C20: 6114.30.30.30 | D20: 00BC14 | E20: Of man-made fibres | F20: BODY: 13% ELASTANE / 14% ELASTANE / 86% POLYAMIDE / 87% POLYAMIDE - LINING: 10% ELASTANE / 7% ELASTANE / 8% ELASTANE / 90% POLYAMIDE / 92% POLYAMIDE / 93% POLYAMIDE / - 10% ELASTANE / 13% ELASTANE / 87% POLYAMIDE / 90% POLYAMIDE | G20: LIVE Short Bodysuit | I20: 3 | J20: 2 | K20: 1
A21: 2799646 | B21: P1472 | C21: 6104.63.10.20 | D21: 00BC14 | E21: Of synthetic fibres | F21: BODY: 13% ELASTANE / 13% ELASTANE / 87% POLYAMIDE / 87% POLYAMIDE - LINING: 10% ELASTANE / 7% ELASTANE / 8% ELASTANE / 90% POLYAMIDE / 92% POLYAMIDE / 93% POLYAMIDE | G21: LIVE Full Length Legging | I21: 3 | J21: 3 | K21: 2
A22: 2799646 | B22: P1479 | C22: 6104.63.10.20 | D22: 00BC14 | E22: Of synthetic fibres | F22: BODY: 13% ELASTANE / 87% POLYAMIDE - LINING: 10% ELASTANE / 7% ELASTANE / 90% POLYAMIDE / 93% POLYAMIDE / - 13% ELASTANE / 87% POLYAMIDE | G22: LIVE Fit Short | H22: 1 | J22: 2
A23: 2799646 | B23: P1497 | C23: 6104.63.10.20 | D23: 00BC01 | E23: Of synthetic fibres | F23: BODY: 12% ELASTANE / 88% POLYAMIDE - LINING: 10% ELASTANE / 90% POLYAMIDE / - 12% ELASTANE / 88% POLYAMIDE | G23: Maxi LIVE Short | I23: 10 | J23: 6 | K23: 4 | L23: 1
A24: 2799646 | B24: P1498 | C24: 6104.63.10.20 | D24: 0AZ190 | E24: Of synthetic fibres | F24: 12% ELASTANE / 88% POLYAMIDE | G24: Maxi LIVE Leggings | K24: 1
A25: 2799646 | B25: P1499 | C25: 6202.40.15.10 | D25: 00BC01 | E25: Of synthetic fibres | F25: BODY AND LINING: 10% ELASTANE / 90% POLYESTER | G25: Maxi LIVE Jacket | K25: 4
A26: 2799646 | B26: P1559 | C26: 6104.63.10.20 | D26: 0AZ190 | E26: Of synthetic fibres | F26: BODY: 12% ELASTANE / 12% ELASTANE / 88% POLYAMIDE / 88% POLYAMIDE - LINING: 10% ELASTANE / 7% ELASTANE / 7% ELASTANE / 8% ELASTANE / 90% POLYAMIDE / 92% POLYAMIDE / 93% POLYAMIDE / 93% POLYAMIDE | G26: Hydefit Adaptiv Legging | K26: 2 | L26: 1
A27: 2799646 | B27: P1560 | C27: 6114.30.30.30 | D27: 00BC01 | E27: Of man-made fibres | F27: PRINTEC FABRIC AND SOLID COLOR FABRIC: 12% ELASTANE / 88% POLYAMIDE / - PRINTED FABRIC AND SOLID COLOR FABRIC: 12% ELASTANE / 88% POLYAMIDE / - 12% ELASTANE / 88% POLYAMIDE | G27: Reversible LIVE Multi Bra | K27: 1 | L27: 3
A28: 2799646 | B28: P1560 | C28: 6114.30.30.30 | D28: 0AZ190 | E28: Of man-made fibres | F28: PRINTEC FABRIC AND SOLID COLOR FABRIC: 12% ELASTANE / 88% POLYAMIDE / - PRINTED FABRIC AND SOLID COLOR FABRIC: 12% ELASTANE / 88% POLYAMIDE / - 12% ELASTANE / 88% POLYAMIDE | G28: Reversible LIVE Multi Bra | J28: 2
A29: 2799646 | B29: P1581 | C29: 6104.63.10.20 | D29: 00BC01 | E29: Of synthetic fibres | F29: BODY: 18% ELASTANE / 82% POLYAMIDE - LINING: 10% ELASTANE / 90% POLYAMIDE | G29: Allure Adaptiv Fit Shorts | I29: 4 | J29: 3 | K29: 2
A30: 2799646 | B30: P1589 | C30: 6114.30.30.30 | D30: 00BC14 | E30: Of man-made fibres | F30: BODY: 12% ELASTANE / 88% POLYAMIDE - LINING: 10% ELASTANE / 90% POLYAMIDE | G30: Top LIVE Icon | I30: 3 | J30: 3 | K30: 2 | L30: 1
A31: 2799646 | B31: P1590 | C31: 6104.63.10.20 | D31: 00BC14 | E31: Of synthetic fibres | F31: BODY: 12% ELASTANE / 88% POLYAMIDE - LINING: 10% ELASTANE / 90% POLYAMIDE / - 12% ELASTANE / 88% POLYAMIDE | G31: LIVE Icon Fit Short | I31: 3 | K31: 2 | L31: 1
A32: 2799646 | B32: P1591 | C32: 6104.63.10.20 | D32: 00BC14 | E32: Of synthetic fibres | F32: BODY: 12% ELASTANE / 88% POLYAMIDE - LINING: 10% ELASTANE / 90% POLYAMIDE | G32: LIVE Icon Legging | I32: 2 | J32: 2 | L32: 1
A33: 2799646 | B33: P1593 | C33: 6109.90.80.10 | D33: 00BC01 | E33: Of other textile materials | F33: 8% ELASTANE / 92% POLYAMIDE | G33: Thermo Skin LS T Shirt | I33: 3 | K33: 2
A34: 2799646 | B34: P1596 | C34: 6104.63.10.20 | D34: 00BC01 | E34: Of synthetic fibres | F34: BODY: 12% ELASTANE / 88% POLYAMIDE - LINING: 10% ELASTANE / 90% POLYAMIDE | G34: Maxi LIVE Leggings | I34: 8 | L34: 2
A35: 2799646 | B35: P1601 | C35: 6102.20.00.10 | D35: 00BC01 | E35: Of cotton | F35: BODY AND HOOD LINING: 32% POLYESTER / 68% COTTON / - 32% POLYESTER / 68% COTTON | G35: Welfare Hoodie | H35: 3 | I35: 3 | J35: 2 | K35: 1
A36: 2799646 | B36: P1602 | C36: 6104.62.10.20 | D36: 00BC01 | E36: Of cotton | F36: BODY AND POCKET LINING: 32% POLYESTER / 68% COTTON / - 32% POLYESTER / 68% COTTON | G36: Welfare Short | H36: 2 | K36: 1
A37: 2799646 | B37: P1603 | C37: 6104.62.10.20 | D37: 00BC01 | E37: Of cotton | F37: BODY AND POCKET LINING: 32% POLYESTER / 32% POLYESTER / 68% COTTON / 68% COTTON / - 32% POLYESTER / 32% POLYESTER / 68% COTTON / 68% COTTON | G37: Welfare Jogger Pant | H37: 3 | I37: 1 | J37: 2 | K37: 1
A38: 2799646 | B38: P1628 | C38: 6102.30.20.10 | D38: 0AZ190 | E38: Of man-made fibres | F38: 8% ELASTANE / 9% ELASTANE / 91% POLYAMIDE / 92% POLYAMIDE | G38: Harmony Jacket Pro | H38: 1 | K38: 1
A39: 2799646 | B39: P1629 | C39: 6114.30.30.30 | D39: 0AZ190 | E39: Of man-made fibres | F39: BODY: 21% ELASTANE / 24% ELASTANE / 76% POLYAMIDE / 79% POLYAMIDE / - CUP COATING AND HANDLES LINING: 100% POLYESTER / 100% POLYESTER / - FRONT LINING: 10% ELASTANE / 10% ELASTANE / 90% POLYAMIDE / 90% POLYAMIDE | G39: Speed Bra | H39: 2 | I39: 3 | J39: 2 | K39: 2
A40: 2799646 | B40: P1666 | C40: 6114.30.30.30 | D40: 00BC01 | E40: Of man-made fibres | F40: 10% ELASTANE / 13% ELASTANE / 13% ELASTANE / 87% POLYAMIDE / 87% POLYAMIDE / 90% POLYAMIDE | G40: Sense Motion Slim Bra | H40: 1 | I40: 4
...

Sheet PACKING LIST
A1: PACKING LIST | M1: C-129/2026
A4: EXPORTER AND MANUFACTURER | M4: Date: 06/24/2026
A5: Live Roupas Esportivas LTDA | M5: Country of Origin: | N5: Port of Destiation
A6: Rua Manoel Francisco da Costa, 1600, Predio 01, Piso 02
A7: Vieira - Jaraguá do Sul - SC | M7: Jaraguá do Sul/BR | N7: Miami / USA
A8: Brasil | M8: Total Net Weight (kg): | N8: Total Gross Weight (kg):
A9: exports@liveoficial.com.br
A10: 89257-207 | M10: =N112 -> 34.32 | N10: =N116 -> 38.4
A11: Tel.: 55 47 2106-7400 | M11: Country of Origin: | N11: Carrier:
M12: Brazil | N12: 0
A13: CONSIGNEE | R13: =N10-M10 -> 4.08
A14: CLIENTE / CUSTOMER: | D14: LIVE! CLOTHING LLC - EIN 371775533
A15: CONTACT PERSON: | D15: Cintia Netto
A16: ENDEREÇO/ ADDRESS: | D16: 723 Lincoln Road
A17: CEP / ZIP CODE: | D17: 33139
A18: CIDADE / CITY: | D18: Miami
A19: PAÍS / COUNTRY: | D19: United States of America
A20: EMAIL: | D20: ecommerce@liveclothing.com
A21: TEL: | D21: (305) 537-4910 / (561) 543-5998
A22: CONSIGNATARIO / CONSIGNEE: | D22: LIVE! CLOTHING LLC - EIN 371775533
A23: CONTACT PERSON: | D23: Cintia Netto
A24: ENDEREÇO/ ADDRESS: | D24: 723 Lincoln Road
A25: CEP / ZIP CODE: | D25: 33139
A26: CIDADE / CITY: | D26: Miami
A27: PAÍS / COUNTRY: | D27: United States of America
A28: EMAIL: | D28: ecommerce@liveclothing.com
A29: TEL: | D29: (305) 537-4910 / (561) 543-5998
A30: INCOTERM: | B30: CIP
A31: TERMS OF PAYMENT: | C31: 365 Days After Invoice Date
A32: NOTE: PO 1586948
A33: BOX | B33: REFERENCE | C33: HS CODE | D33: COLOR | E33: PRODUCT MATERIAL | F33: DESCRIPTION | G33: XS | H33: S | I33: M | J33: L | K33: XL | L33: UNIT | M33: UNIT WEIGHT | N33: TOTAL WEIGHT
A34: 3744887 | B34: P1153 | C34: 6109.90.80.10 | D34: 00BC14 | E34: Of other textile materials | F34: LIVE Comfort TShirt | I34: 2 | K34: 1 | L34: =SUM(G34:K34) -> 3 | M34: 0.12452542 | N34: =M34*L34 -> 0.37357627 | Q34: =M34+0.003 -> 0.12752542 | R34: =VLOOKUP(B34,#REF!,13,0) -> #REF! | S34: =R34*L34 -> #REF! | T34: =M34+0.018415205 -> 0.14294063 | U34: =VLOOKUP(B34,'SOLVER NOVO'!A:E,5,) -> 9.1533296 | V34: =M34+0.017525424 -> 0.14205085
A35: 3744887 | B35: P6200 | C35: 6114.30.30.30 | D35: 00BC01 | E35: Of man-made fibres | F35: Sense Slim BT Bra | J35: 2 | L35: =SUM(G35:K35) -> 2 | M35: 0.10252542 | N35: =M35*L35 -> 0.20505085 | V35: =M35+0.017525424 -> 0.12005085
A36: 3744887 | B36: P1154 | C36: 6106.20.10.10 | D36: 00RX80 | E36: Of man-made fibres | F36: LIVE Comfort Tank Top | J36: 2 | K36: 1 | L36: =SUM(G36:K36) -> 3 | M36: 0.12052542 | N36: =M36*L36 -> 0.36157627 | V36: =M36+0.017525424 -> 0.13805085
A37: 3744887 | B37: P1222 | C37: 6114.30.30.30 | D37: 00BC14 | E37: Of man-made fibres | F37: LIVE Move Bra | J37: 2 | L37: =SUM(G37:K37) -> 2 | M37: 0.11252542 | N37: =M37*L37 -> 0.22505085 | V37: =M37+0.017525424 -> 0.13005085
A38: 3744887 | B38: P1437 | C38: 6114.30.30.30 | D38: 00BC14 | E38: Of man-made fibres | F38: LIVE Short Bodysuit | H38: 3 | J38: 1 | L38: =SUM(G38:K38) -> 4 | M38: 0.15252542 | N38: =M38*L38 -> 0.6101017 | V38: =M38+0.017525424 -> 0.17005085
A39: 3744887 | B39: P1479 | C39: 6104.63.10.20 | D39: 00BC14 | E39: Of synthetic fibres | F39: LIVE Fit Short | I39: 2 | L39: =SUM(G39:K39) -> 2 | M39: 0.13752542 | N39: =M39*L39 -> 0.27505085 | V39: =M39+0.017525424 -> 0.15505085
A40: 3744887 | B40: P1497 | C40: 6104.63.10.20 | D40: 00BC01 | E40: Of synthetic fibres | F40: Maxi LIVE Short | H40: 10 | L40: =SUM(G40:K40) -> 10 | M40: 0.11752542 | N40: =M40*L40 -> 1.1752542 | V40: =M40+0.017525424 -> 0.13505085
A41: 3744887 | B41: P1499 | C41: 6202.40.15.10 | D41: 00BC01 | E41: Of synthetic fibres | F41: Maxi LIVE Jacket | J41: 4 | L41: =SUM(G41:K41) -> 4 | M41: 0.30252542 | N41: =M41*L41 -> 1.2101017 | V41: =M41+0.017525424 -> 0.32005085
A42: 3744887 | B42: P1560 | C42: 6114.30.30.30 | D42: 00BC01 | E42: Of man-made fibres | F42: Reversible LIVE Multi Bra | J42: 1 | L42: =SUM(G42:K42) -> 1 | M42: 0.11752542 | N42: =M42*L42 -> 0.11752542 | V42: =M42+0.017525424 -> 0.13505085
...

Sheet packing
A1: Order | B1: BOX | C1: Reference | D1: N.C.M. | E1: Color | F1: Product Materials | G1: Description | H1: XS | I1: S | J1: M | K1: L | L1: XL | M1: Unit Weight
A2: 2799646 | B2: 3744887 | C2: P1153 | D2: 6109.90.80.10 | E2: 00BC14 | F2: Of other textile materials | G2: LIVE Comfort TShirt | J2: 2 | L2: 1 | M2: 0.107
A3: 2799646 | B3: 3744887 | C3: P6200 | D3: 6114.30.30.30 | E3: 00BC01 | F3: Of man-made fibres | G3: Sense Slim BT Bra | K3: 2 | M3: 0.085
A4: 2799646 | B4: 3744887 | C4: P1154 | D4: 6106.20.10.10 | E4: 00RX80 | F4: Of man-made fibres | G4: LIVE Comfort Tank Top | K4: 2 | L4: 1 | M4: 0.103
A5: 2799646 | B5: 3744887 | C5: P1222 | D5: 6114.30.30.30 | E5: 00BC14 | F5: Of man-made fibres | G5: LIVE Move Bra | K5: 2 | M5: 0.095
A6: 2799646 | B6: 3744887 | C6: P1437 | D6: 6114.30.30.30 | E6: 00BC14 | F6: Of man-made fibres | G6: LIVE Short Bodysuit | I6: 3 | K6: 1 | M6: 0.135
A7: 2799646 | B7: 3744887 | C7: P1479 | D7: 6104.63.10.20 | E7: 00BC14 | F7: Of synthetic fibres | G7: LIVE Fit Short | J7: 2 | M7: 0.12
A8: 2799646 | B8: 3744887 | C8: P1497 | D8: 6104.63.10.20 | E8: 00BC01 | F8: Of synthetic fibres | G8: Maxi LIVE Short | I8: 10 | M8: 0.1
A9: 2799646 | B9: 3744887 | C9: P1499 | D9: 6202.40.15.10 | E9: 00BC01 | F9: Of synthetic fibres | G9: Maxi LIVE Jacket | K9: 4 | M9: 0.285
A10: 2799646 | B10: 3744887 | C10: P1560 | D10: 6114.30.30.30 | E10: 00BC01 | F10: Of man-made fibres | G10: Reversible LIVE Multi Bra | K10: 1 | M10: 0.1
A11: 2799646 | B11: 3744887 | C11: P1560 | D11: 6114.30.30.30 | E11: 0AZ190 | F11: Of man-made fibres | G11: Reversible LIVE Multi Bra | J11: 2 | M11: 0.075
A12: 2799646 | B12: 3744887 | C12: P1581 | D12: 6104.63.10.20 | E12: 00BC01 | F12: Of synthetic fibres | G12: Allure Adaptiv Fit Shorts | K12: 2 | M12: 0.13
A13: 2799646 | B13: 3744887 | C13: P1589 | D13: 6114.30.30.30 | E13: 00BC14 | F13: Of man-made fibres | G13: Top LIVE Icon | I13: 3 | K13: 2 | M13: 0.089
A14: 2799646 | B14: 3744887 | C14: P1590 | D14: 6104.63.10.20 | E14: 00BC14 | F14: Of synthetic fibres | G14: LIVE Icon Fit Short | L14: 1 | M14: 0.14
A15: 2799646 | B15: 3744887 | C15: P1596 | D15: 6104.63.10.20 | E15: 00BC01 | F15: Of synthetic fibres | G15: Maxi LIVE Leggings | I15: 3 | M15: 0.1
A16: 2799646 | B16: 3744887 | C16: P1601 | D16: 6102.20.00.10 | E16: 00BC01 | F16: Of cotton | G16: Welfare Hoodie | I16: 2 | M16: 0.27
A17: 2799646 | B17: 3744887 | C17: P1602 | D17: 6104.62.10.20 | E17: 00BC01 | F17: Of cotton | G17: Welfare Short | H17: 2 | K17: 1 | M17: 0.115
A18: 2799646 | B18: 3744887 | C18: P1603 | D18: 6104.62.10.20 | E18: 00BC01 | F18: Of cotton | G18: Welfare Jogger Pant | H18: 3 | J18: 2 | M18: 0.216
A19: 2799646 | B19: 3744887 | C19: P1628 | D19: 6102.30.20.10 | E19: 0AZ190 | F19: Of man-made fibres | G19: Harmony Jacket Pro | K19: 1 | M19: 0.255
A20: 2799646 | B20: 3744887 | C20: P1629 | D20: 6114.30.30.30 | E20: 0AZ190 | F20: Of man-made fibres | G20: Speed Bra | H20: 2 | I20: 3 | M20: 0.083
A21: 2799646 | B21: 3744887 | C21: P1666 | D21: 6114.30.30.30 | E21: 00BC01 | F21: Of man-made fibres | G21: Sense Motion Slim Bra | I21: 4 | M21: 0.08
A22: 2799646 | B22: 3744887 | C22: P1927 | D22: 6106.20.10.10 | E22: 00BC01 | F22: Of man-made fibres | G22: Sense Move Crop Tank | K22: 3 | M22: 0.09
A23: 2799646 | B23: 3744887 | C23: P1153 | D23: 6109.90.80.10 | E23: 0AZ190 | F23: Of other textile materials | G23: LIVE Comfort TShirt | K23: 1 | M23: 0.11
A24: 2799646 | B24: 3745328 | C24: 46591 | D24: 6104.63.10.20 | E24: 00RX80 | F24: Of synthetic fibres | G24: Seamless Mesh Full Legging | J24: 2 | M24: 0.35
A25: 2799646 | B25: 3745328 | C25: 46592 | D25: 6114.30.30.30 | E25: 00RX80 | F25: Of man-made fibres | G25: Seamless Knit Short Bodysuit | H25: 1 | M25: 0.215
A26: 2799646 | B26: 3745328 | C26: P0063 | D26: 6114.30.30.30 | E26: 00BC14 | F26: Of man-made fibres | G26: LIVE Curve Bra | I26: 3 | M26: 0.065
A27: 2799646 | B27: 3745328 | C27: P1153 | D27: 6109.90.80.10 | E27: 00BC14 | F27: Of other textile materials | G27: LIVE Comfort TShirt | H27: 1 | I27: 3 | J27: 1 | M27: 0.09
A28: 2799646 | B28: 3745328 | C28: P1153 | D28: 6109.90.80.10 | E28: 00RX80 | F28: Of other textile materials | G28: LIVE Comfort TShirt | K28: 2 | M28: 0.11
A29: 2799646 | B29: 3745328 | C29: P1153 | D29: 6109.90.80.10 | E29: 0AZ190 | F29: Of other textile materials | G29: LIVE Comfort TShirt | H29: 1 | I29: 1 | M29: 0.085
A30: 2799646 | B30: 3745328 | C30: P1213 | D30: 6106.20.10.10 | E30: 00BC14 | F30: Of man-made fibres | G30: LIVE Comfort Crop Tank | L30: 1 | M30: 0.08
A31: 2799646 | B31: 3745328 | C31: P1213 | D31: 6106.20.10.10 | E31: 00RX80 | F31: Of man-made fibres | G31: LIVE Comfort Crop Tank | L31: 1 | M31: 0.08
A32: 2799646 | B32: 3745328 | C32: P1226 | D32: 6104.63.10.20 | E32: 00RX80 | F32: Of synthetic fibres | G32: LIVE Icon Neo Full Legging | I32: 3 | M32: 0.2
A33: 2799646 | B33: 3745328 | C33: P1434 | D33: 6114.30.30.30 | E33: 00RX80 | F33: Of man-made fibres | G33: Sense Curve Bra | H33: 1 | J33: 3 | M33: 0.068
A34: 2799646 | B34: 3745328 | C34: P1472 | D34: 6104.63.10.20 | E34: 00BC14 | F34: Of synthetic fibres | G34: LIVE Full Length Legging | I34: 3 | K34: 2 | M34: 0.216
A35: 2799646 | B35: 3745328 | C35: P1497 | D35: 6104.63.10.20 | E35: 00BC01 | F35: Of synthetic fibres | G35: Maxi LIVE Short | L35: 1 | M35: 0.13
A36: 2799646 | B36: 3745328 | C36: P1498 | D36: 6104.63.10.20 | E36: 0AZ190 | F36: Of synthetic fibres | G36: Maxi LIVE Leggings | K36: 1 | M36: 0.22
A37: 2799646 | B37: 3745328 | C37: P1559 | D37: 6104.63.10.20 | E37: 0AZ190 | F37: Of synthetic fibres | G37: Hydefit Adaptiv Legging | K37: 2 | L37: 1 | M37: 0.227
A38: 2799646 | B38: 3745328 | C38: P1581 | D38: 6104.63.10.20 | E38: 00BC01 | F38: Of synthetic fibres | G38: Allure Adaptiv Fit Shorts | J38: 3 | M38: 0.12
A39: 2799646 | B39: 3745328 | C39: P1589 | D39: 6114.30.30.30 | E39: 00BC14 | F39: Of man-made fibres | G39: Top LIVE Icon | L39: 1 | M39: 0.1
A40: 2799646 | B40: 3745328 | C40: P1590 | D40: 6104.63.10.20 | E40: 00BC14 | F40: Of synthetic fibres | G40: LIVE Icon Fit Short | K40: 2 | M40: 0.13
...

Sheet SOLVER NOVO
A1: REF | B1: NCM | C1: QTY PEÇAS | D1: DOLAR 2019 | E1: VALOR UNIT DOL | F1: VALOR DOL TOTAL | G1: VALOR UNIT REAL
A2: 46586 | B2: 6114.30.00 | C2: 8 | D2: =VLOOKUP(A2,TIMELESS!A:C,3,FALSE) -> 22.78 | E2: 8.6141795 | F2: =E2*C2 -> 68.913436 | G2: =E2*5.1737 -> 44.56718
A3: 46587 | B3: 6104.63.00 | C3: 5 | D3: =VLOOKUP(A3,TIMELESS!A:C,3,FALSE) -> 18.18 | E3: 8.7496168 | F3: =E3*C3 -> 43.748084 | G3: =E3*5.1737 -> 45.267893
A4: 46588 | B4: 6104.63.00 | C4: 6 | D4: =VLOOKUP(A4,TIMELESS!A:C,3,FALSE) -> 27.38 | E4: 10.493706 | F4: =E4*C4 -> 62.962235 | G4: =E4*5.1737 -> 54.291286
A5: 46589 | B5: 6104.63.00 | C5: 5 | D5: =VLOOKUP(A5,TIMELESS!A:C,3,FALSE) -> 34.58 | E5: 9.0113994 | F5: =E5*C5 -> 45.056997 | G5: =E5*5.1737 -> 46.622277
A6: 46590 | B6: 6114.30.00 | C6: 5 | D6: =VLOOKUP(A6,TIMELESS!A:C,3,FALSE) -> 22.78 | E6: 9.7850352 | F6: =E6*C6 -> 48.925176 | G6: =E6*5.1737 -> 50.624837
A7: 46591 | B7: 6104.63.00 | C7: 5 | D7: =VLOOKUP(A7,TIMELESS!A:C,3,FALSE) -> 22.78 | E7: 9.6712217 | F7: =E7*C7 -> 48.356108 | G7: =E7*5.1737 -> 50.036 | J7: =SUM(F2:F166) -> 4055.3476
A8: 46592 | B8: 6114.30.00 | C8: 6 | D8: =VLOOKUP(A8,TIMELESS!A:C,3,FALSE) -> 39.18 | E8: 9.764121 | F8: =E8*C8 -> 58.584726 | G8: =E8*5.1737 -> 50.516633 | J8: =J7*5.1737 -> 20981.152
A9: P0063 | B9: 6114.30.00 | C9: 9 | D9: =VLOOKUP(A9,TIMELESS!A:C,3,FALSE) -> 19.98 | E9: 11.37848 | F9: =E9*C9 -> 102.40632 | G9: =E9*5.1737 -> 58.868842
A10: P1153 | B10: 6109.90.00 | C10: 22 | D10: =VLOOKUP(A10,PULSE!A:C,3,0) -> 18.18 | E10: 9.1533296 | F10: =E10*C10 -> 201.37325 | G10: =E10*5.1737 -> 47.356582
A11: P1154 | B11: 6106.20.00 | C11: 18 | D11: =VLOOKUP(A11,PULSE!A:C,3,0) -> 17.38 | E11: 7.817765 | F11: =E11*C11 -> 140.71977 | G11: =E11*5.1737 -> 40.446771
A12: P1213 | B12: 6106.20.00 | C12: 15 | D12: =VLOOKUP(A12,PULSE!A:C,3,0) -> 15.58 | E12: 8.7312149 | F12: =E12*C12 -> 130.96822 | G12: =E12*5.1737 -> 45.172687
A13: P1222 | B13: 6114.30.00 | C13: 9 | D13: =VLOOKUP(A13,PULSE!A:C,3,0) -> 23.78 | E13: 9.0584904 | F13: =E13*C13 -> 81.526413 | G13: =E13*5.1737 -> 46.865912
A14: P1225 | B14: 6104.63.00 | C14: 6 | D14: =VLOOKUP(A14,PULSE!A:C,3,FALSE) -> 21.98 | E14: 8.7623457 | F14: =E14*C14 -> 52.574074 | G14: =E14*5.1737 -> 45.333748
A15: P1226 | B15: 6104.63.00 | C15: 8 | D15: =VLOOKUP(A15,PULSE!A:C,3,0) -> 29.18 | E15: 10.234378 | F15: =E15*C15 -> 81.875022 | G15: =E15*5.1737 -> 52.9496
A16: P1298 | B16: 6114.30.00 | C16: 6 | D16: =VLOOKUP(A16,PULSE!A:C,3,0) -> 22.78 | E16: 10.644185 | F16: =E16*C16 -> 63.865108 | G16: =E16*5.1737 -> 55.069818
A17: P1434 | B17: 6114.30.00 | C17: 10 | D17: =VLOOKUP(A17,PULSE!A:C,3,0) -> 17.38 | E17: 7.0815216 | F17: =E17*C17 -> 70.815216 | G17: =E17*5.1737 -> 36.637668
A18: P1437 | B18: 6114.30.00 | C18: 6 | D18: =VLOOKUP(A18,PULSE!A:C,3,0) -> 36.38 | E18: 8.7935381 | F18: =E18*C18 -> 52.761229 | G18: =E18*5.1737 -> 45.495128
A19: P1472 | B19: 6104.63.00 | C19: 9 | D19: =VLOOKUP(A19,PULSE!A:C,3,0) -> 29.98 | E19: 6.7037163 | F19: =E19*C19 -> 60.333447 | G19: =E19*5.1737 -> 34.683017
A20: P1479 | B20: 6104.63.00 | C20: 6 | D20: =VLOOKUP(A20,PULSE!A:C,3,0) -> 22.78 | E20: 10.655789 | F20: =E20*C20 -> 63.934734 | G20: =E20*5.1737 -> 55.129855
A21: P1497 | B21: 6104.63.00 | C21: 21 | D21: =VLOOKUP(A21,PULSE!A:C,3,0) -> 21.98 | E21: 9.5763917 | F21: =E21*C21 -> 201.10423 | G21: =E21*5.1737 -> 49.545378
A22: P1498 | B22: 6104.63.00 | C22: 5 | D22: =VLOOKUP(A22,PULSE!A:C,3,0) -> 29.98 | E22: 8.4328336 | F22: =E22*C22 -> 42.164168 | G22: =E22*5.1737 -> 43.628951
A23: P1499 | B23: 6202.40.00 | C23: 21 | D23: =VLOOKUP(A23,PULSE!A:C,3,0) -> 45.58 | E23: 12.359676 | F23: =E23*C23 -> 259.5532 | G23: =E23*5.1737 -> 63.945258
A24: P1559 | B24: 6104.63.00 | C24: 9 | D24: =VLOOKUP(A24,PULSE!A:C,3,0) -> 16.38 | E24: 9.9844301 | F24: =E24*C24 -> 89.859871 | G24: =E24*5.1737 -> 51.656446
A25: P1560 | B25: 6114.30.00 | C25: 26 | D25: =VLOOKUP(A25,PULSE!A:C,3,0) -> 22.78 | E25: 12.427872 | F25: =E25*C25 -> 323.12468 | G25: =E25*5.1737 -> 64.298083
A26: P1581 | B26: 6104.63.00 | C26: 12 | D26: =VLOOKUP(A26,PULSE!A:C,3,0) -> 21.98 | E26: 11.493431 | F26: =E26*C26 -> 137.92117 | G26: =E26*5.1737 -> 59.463565
... A29: P1591 | B29: 6104.63.00 | C29: 7 | D29: =VLOOKUP(A29,PULSE!A:C,3,0) -> 29.98 | E29: 10.493545 | F29: =E29*C29 -> 73.454818 | G29: =E29*5.1737 -> 54.290456
A30: P1593 | B30: 6109.90.00 | C30: 8 | D30: =VLOOKUP(A30,TIMELESS!A:C,3,FALSE) -> 19.98 | E30: 10.597997 | F30: =E30*C30 -> 84.783975 | G30: =E30*5.1737 -> 54.830856
A31: P1596 | B31: 6104.63.00 | C31: 20 | D31: =VLOOKUP(A31,PULSE!A:C,3,FALSE) -> 29.98 | E31: 8.993111 | F31: =E31*C31 -> 179.86222 | G31: =E31*5.1737 -> 46.527658
A32: P1601 | B32: 6102.20.00 | C32: 9 | D32: =VLOOKUP(A32,PULSE!A:C,3,0) -> 45.58 | E32: 10.754326 | F32: =E32*C32 -> 96.788935 | G32: =E32*5.1737 -> 55.639657
A33: P1602 | B33: 6104.62.00 | C33: 7 | D33: =VLOOKUP(A33,PULSE!A:C,3,0) -> 27.38 | E33: 10.570831 | F33: =E33*C33 -> 73.995814 | G33: =E33*5.1737 -> 54.690306
A34: P1603 | B34: 6104.62.00 | C34: 9 | D34: =VLOOKUP(A34,PULSE!A:C,3,0) -> 45.58 | E34: 9.961564 | F34: =E34*C34 -> 89.654076 | G34: =E34*5.1737 -> 51.538144
A35: P1628 | B35: 6102.30.00 | C35: 7 | D35: =VLOOKUP(A35,PULSE!A:C,3,0) -> 34.58 | E35: 10.504166 | F35: =E35*C35 -> 73.529161 | G35: =E35*5.1737 -> 54.345403
A36: P1629 | B36: 6114.30.00 | C36: 9 | D36: =VLOOKUP(A36,PULSE!A:C,3,0) -> 29.18 | E36: 10.702448 | F36: =E36*C36 -> 96.322034 | G36: =E36*5.1737 -> 55.371256
A37: P1666 | B37: 6114.30.00 | C37: 13 | D37: =VLOOKUP(A37,PULSE!A:C,3,0) -> 19.98 | E37: 10.920884 | F37: =E37*C37 -> 141.97149 | G37: =E37*5.1737 -> 56.501378
A38: P1927 | B38: 6106.20.00 | C38: 17 | D38: =VLOOKUP(A38,PULSE!A:C,3,0) -> 19.98 | E38: 11.437603 | F38: =E38*C38 -> 194.43925 | G38: =E38*5.1737 -> 59.174727
A39: P6200 | B39: 6114.30.00 | C39: 20 | D39: =VLOOKUP(A39,PULSE!A:C,3,0) -> 17.38 | E39: 12.150155 | F39: =E39*C39 -> 243.00311 | G39: =E39*5.1737 -> 62.861258

Sheet TIMELESS
A1: Referência | B1: Descrição | C1: Dólar
A2: 46557 | B2: UNISEX LIVE LONG SOCK | C2: 8.18
A3: 46562 | B3: REFLEX RACE PRO TOP | C3: 31.98
A4: 46563 | B4: REFLEX RACE PRO SHORTS | C4: 29.98
A5: 46564 | B5: RACE PRO REFLEX LEGGINGS | C5: 36.38
A6: 46565 | B6: AERO AIR MOVE TANK TOP | C6: 18.18
A7: 46566 | B7: AERO AIR MOVE T-SHIRT | C7: 19.98
A8: 46567 | B8: FRESH PRO GRAPHENE TOP | C8: 31.98
A9: 46568 | B9: FRESH PRO GRAPHENE SHORTS | C9: 33.78
A10: 46569 | B10: FRESH PRO GRAPHENE LEGGINGS | C10: 45.58
A11: 46570 | B11: FRESH PRO GRAPHENE TANK TOP | C11: 27.38
A12: 46573 | B12: ACE HYDEFIT ADAPTIV TOP | C12: 29.18
A13: 46574 | B13: ACE HYDEFIT ADAPTIV SKIRT | C13: 34.58
... A160: 46971 | B160: TRAIN EQUILIBRIUM COMFY TANK TOP | C160: 23.78
A161: F2791 | B161: MEN'S BIKE SLIM SHIRT | C161: 45.58
A162: F2792 | B162: BIKE 9 MEN SHORTS | C162: 31.98
A163: F2793 | B163: BM TRIATHLON MEN JUMPSUIT | C163: 59.18
A164: F2794 | B164: HARMONY BIKE SHIRT | C164: 45.58
A165: F2795 | B165: RACE PRO BIKE SHORTS | C165: 31.98
A166: F2796 | B166: BM TRIATHLON JUMPSUIT | C166: 59.18
A167: F2808 | B167: BIB SHORTS MEN | C167: 40.98
A168: F2809 | B168: BIB SHORTS RACE PRO BIKE | C168: 40.98
A169: I2129 | B169: MODAL SOFT SHORTS | C169: 40.98
A170: I2130 | B170: FUSION SKIN LEGGINGS | C170: 63.78
A171: I2131 | B171: FUSION SKIN RACERBACK TOP | C171: 54.58
A172: I2132 | B172: AERIS FORM JACKET | C172: 63.78
... A443: P8111 | B443: TRAIN COMFY MEN T-SHIRT | C443: 17.38
A444: 45716 | B444: LUMINA KNIT SHORTS SET | C444: 54.58
A445: 45719 | B445: LUMINA KNIT JUMPSUIT | C445: 49.98
A446: 45720 | B446: MIDI DRESS LUMINA KNIT | C446: 77.38
A447: 45724 | B447: ACQUA TOP AND THONG SET | C447: 45.98
A448: 45725 | B448: ORBIT ACQUA BATHING SUIT | C448: 45.98
A449: 45726 | B449: ML LINEUP ACQUA BATHING SUIT | C449: 49.98
A450: 45727 | B450: ML ZIP ACQUA CROPPED BLOUSE | C450: 31.98
A451: 45728 | B451: ML ACQUA BLOUSE | C451: 27.38
A452: 45729 | B452: ALLURE ADAPTIV TRIANGLE TOP | C452: 20.98
A453: 45730 | B453: ALLURE ADAPTIV TIE THONG | C453: 20.98
A454: 45731 | B454: ALLURE ADAPTIV TRIANGLE TOP | C454: 21.78
A455: 45732 | B455: ALLURE ADAPTIV HANG GLIDING THONG | C455: 14.18
... A499: 45790 | B499: SENSE KIDS SWIMSUIT | C499: 20.98
...

Sheet PULSE
A1: Referência | B1: Descrição | C1: Dólar
A2: 61855 | B2: Top Stride Softness | C2: 22.78
A3: 61856 | B3: Shorts Stride Softness | C3: 22.78
A4: 61857 | B4: Stride Softness Pants | C4: 27.38
A5: 61862 | B5: Legging Curve Sparkflow | C5: 22.78
A6: 61865 | B6: Top Trace Upfit | C6: 25.58
A7: 61867 | B7: Upfit Leggings | C7: 27.38
A8: 61870 | B8: Split Jog Jacket | C8: 36.38
A9: 61871 | B9: Barrel Jog Pants | C9: 40.98
A10: 61872 | B10: Long Balloon Jog Jumpsuit | C10: 54.58
A11: 61877 | B11: Cropped Long Nylon Net Jacket | C11: 54.58
A12: 85330 | B12: Top Halter ByNature | C12: 25.58
A13: 85331 | B13: Shorts ByNature | C13: 29.98
... A267: 61971 | B267: Run Move 9 Men's Shorts | C267: 36.38
A268: F2364 | B268: LIVE BT Bag | C268: 16.38
A269: F2418 | B269: Seamless Shorts Jumpsuit | C269: 29.98
A270: F2764 | B270: Seamless Knit Jumpsuit | C270: 32.78
A271: F2764 | B271: Seamless Knit Jumpsuit | C271: 32.78
A272: F2791 | B272: Bike Slim Men Shirt | C272: 45.58
A273: F2792 | B273: Shorts Bike 9 Men | C273: 31.98
A274: F2793 | B274: BM Triathlon Men Jumpsuit | C274: 59.18
A275: F2794 | B275: Harmony Bike Shirt | C275: 45.58
A276: F2795 | B276: Race Pro Bike Shorts | C276: 31.98
A277: F2796 | B277: BM Triathlon Jumpsuit | C277: 59.18
A278: F2808 | B278: Bretelle Bike Men | C278: 40.98
A279: F2809 | B279: Bretelle Race Pro Bike | C279: 40.98
... A623: P1686 | B623: Energy Dry Towel | C623: 7.38
A624: P1696 | B624: 0 | C624: 36.38
A625: P1697 | B625: 0 | C625: 40.98
A626: P1698 | B626: 0 | C626: 27.38
A627: P1719 | B627: Thermo Color Glove | C627: 15.58
A628: P1927 | B628: Cropped Tank Top Move Sense | C628: 19.98
A629: P4405 | B629: Fast Running Sock | C629: 5.58
A630: P6200 | B630: Top Slim BT Sense | C630: 17.38
A631: P8111 | B631: Train Comfy Men T-Shirt | C631: 16.38
A632: P8111 | B632: Train Comfy Men T-Shirt | C632: 16.38

Sheet ORIGINS
A1: Referência | B1: Descrição | D1: Dólar
A2: 46277 | B2: GRADIENT SEAMLESS KNIT® TOP | C2: 113.9 | D2: 22.78
A3: 46278 | B3: GRADIENT SEAMLESS KNIT® LEGGINGS | C3: 99.9 | D3: 19.98
A4: 46279 | B4: SEAMLESS KNIT® EDGE TOP | C4: 118.9 | D4: 23.78
A5: 46280 | B5: SEAMLESS KNIT® EDGE LEGGING | C5: 113.9 | D5: 22.78
A6: 46283 | B6: TOP V SWIMMER NEOPRENE FIT | C6: 113.9 | D6: 22.78
A7: 46284 | B7: BERMUDA NEOPRENE FIT | C7: 113.9 | D7: 22.78
A8: 46285 | B8: FIT NEOPRENE LEGGINGS | C8: 127.9 | D8: 25.58
A9: 46286 | B9: HALTER AIR MOVE TANK TOP® | C9: 77.9 | D9: 15.58
A10: 46287 | B10: AIR MOVE® BLOUSE | C10: 77.9 | D10: 15.58
A11: 46288 | B11: AIR MOVE® T-SHIRT | C11: 90.9 | D11: 18.18
A12: 46289 | B12: TOP HYDEFIT® ADAPTIV ACT | C12: 99.9 | D12: 19.98
A13: 46290 | B13: HYDEFIT® ADAPTIV ACT SHORTS | C13: 90.9 | D13: 18.18
... A187: 46551 | B187: LEGGING LIVE! HYDEFIT® ADAPTIV | C187: 145.9 | D187: 29.18
A188: F2364 | B188: LIVE BT BAG | C188: 81.9 | D188: 17.24
A189: F2777 | B189: SEAMLESS KNIT® DIAGONAL SHORTS | C189: 90.9 | D189: 18.926316
A190: F2778 | B190: SEAMLESS DIAGONAL FUSO PANTS | C190: 127.9 | D190: 26.926316
A191: F2780 | B191: SEAMLESS DIAGONAL JUMPSUIT | C191: 181.9 | D191: 38.294737
A192: F2782 | B192: SEAMLESS DIAGONAL JACKET | C192: 272.9 | D192: 57.452632
A193: F2797 | B193: BIKE VELOCI STRIPES T-SHIRT | C193: 195.9 | D193: 41.242105
A194: F2798 | B194: TRIATHLON BERMUDA JUMPSUIT | C194: 295.9 | D194: 62.294737
A195: F2799 | B195: RACE PRO® HARMONY BIKE SHORTS | C195: 181.9 | D195: 38.294737
A196: F2800 | B196: RACE PRO® HARMONY BIKE SHORTS | C196: 159.9 | D196: 33.663158
A197: F2802 | B197: BIKE VELOCI MEN T-SHIRT | C197: 195.9 | D197: 41.242105
A198: F2803 | B198: MEN'S TRIATHLON SHORTS JUMPSUIT | C198: 295.9 | D198: 62.294737
A199: F2804 | B199: RACE PRO MEN BIKE SHORTS | C199: 159.9 | D199: 33.663158
... A465: P8111 | B465: BASIC COMFORT MEN T-SHIRT | C465: 81.9 | D465: 15.35
A466: 45575 | B466: TOP CORTININHA SWAY | C466: 95.9 | D466: 19.18
A467: 45576 | B467: TOP SWAY TRACK | C467: 108.9 | D467: 21.78
A468: 45577 | B468: TOP V SWAY | C468: 108.9 | D468: 21.78
A469: 45578 | B469: SWAY TIE THONG | C469: 95.9 | D469: 19.18
A470: 45579 | B470: SWAY SIDE TIE THONG | C470: 91.9 | D470: 18.38
A471: 45580 | B471: SWAY THONG | C471: 70.9 | D471: 14.18
A472: 45581 | B472: V SWAY SWIMSUIT | C472: 145.9 | D472: 29.18
A473: 45582 | B473: MAXI SAND DUNES TRIANGLE TOP | C473: 99.9 | D473: 19.98
A474: 45583 | B474: TWIST SAND DUNES STRIPE TOP | C474: 108.9 | D474: 21.78
A475: 45584 | B475: TOP LOOP SAND DUNES | C475: 116.9 | D475: 23.38
A476: 45585 | B476: SAND DUNES TIE-UP THONG | C476: 95.9 | D476: 19.18
A477: 45586 | B477: SAND DUNES HANG GLIDING THONG | C477: 66.9 | D477: 13.38
... A592: 45711 | B592: SPELL MIDI DRESS | C592: 204.9 | D592: 40.98
...

Sheet JOURNEY
A1: Referência | B1: Descrição | C1: Description | D1: Sell In | E1: Sell Out | F1: Dólar
A2: P1227 | B2: Top Curve Seamless | C2: SEAMLESS CURVE TOP | D2: 43.9 | E2: 94.9 | F2: =D2/4.75 -> 9.2421053
A3: P1228 | B3: Calcinha Basica Seamless | C3: BASIC SEAMLESS PANTY | D3: 31.9 | E3: 69.9 | F3: =D3/4.75 -> 6.7157895
A4: P1229 | B4: Calcinha String Push Seamless | C4: STRING PUSH SEAMLESS PANT | D4: 34.9 | E4: 74.9 | F4: =D4/4.75 -> 7.3473684
A5: P1383 | B5: Kit Calcinha Fio | C5: THONG PANTY KIT | D5: 59.9 | E5: 129.9 | F5: =D5/4.75 -> 12.610526
A6: P1188 | B6: Top Faixa Seamless | C6: SEAMLESS BANDEAU TOP | D6: 17.9 | E6: 39.9 | F6: =D6/4.75 -> 3.7684211
A7: P1189 | B7: Top Reto Seamless | C7: SEAMLESS STRAIGHT TOP | D7: 36.9 | E7: 79.9 | F7: =D7/4.75 -> 7.7684211
A8: P1191 | B8: Calcinha Fio Basica Seamless | C8: BASIC SEAMLESS THONG | D8: 27.9 | E8: 59.9 | F8: =D8/4.75 -> 5.8736842
A9: P1194 | B9: Calcinha Fio Media Seamless | C9: MEDIUM COVERAGE SEAMLESS THONG | D9: 34.9 | E9: 74.9 | F9: =D9/4.75 -> 7.3473684
A10: P1196 | B10: Cueca Longa Boxer Seamless | C10: LONG BOXER SEAMLESS UNDERWEAR | D10: 40.9 | E10: 89.9 | F10: =D10/4.75 -> 8.6105263
A11: P1195 | B11: Cueca Boxer Seamless | C11: SEAMLESS BOXER BRIEF | D11: 36.9 | E11: 79.9 | F11: =D11/4.75 -> 7.7684211
A12: P1407 | B12: Cinto Seamless | C12: SEAMLESS BELT | D12: 45.9 | E12: 99.9 | F12: =D12/4.75 -> 9.6631579
A13: P1290 | B13: Porta Objetos Live! Movement | C13: LIVE! MOVEMENT ORGANIZER | D13: 45.9 | E13: 99.9 | F13: =D13/4.75 -> 9.6631579
... A128: P1133 | B128: Macacao Allure Adaptiv | C128: ALLURE ADAPTIV JUMPSUIT | D128: 195.9 | E128: 429.9 | F128: =D128/4.75 -> 41.242105
A129: 85091 | B129: Top Allure Matt | C129: ALLURE MATT TOP | D129: 118.9 | E129: 259.9 | F129: =D129/4.75 -> 25.031579
A130: 85092 | B130: Bermuda Allure Matt | C130: ALLURE MATT SHORTS | D130: 113.9 | E130: 249.9 | F130: =D130/4.75 -> 23.978947
A131: 85093 | B131: Calca Allure Matt | C131: ALLURE MATT PANTS | D131: 127.9 | E131: 279.9 | F131: =D131/4.75 -> 26.926316
A132: 85094 | B132: Regata Bio Stretch | C132: BIO STRETCH TANK TOP | D132: 122.9 | E132: 269.9 | F132: =D132/4.75 -> 25.873684
A133: 85095 | B133: Camiseta Bio Stretch | C133: BIO STRETCH T-SHIRT | D133: 158.9 | E133: 349.9 | F133: =D133/4.75 -> 33.452632
A134: 85096 | B134: Top Athletic Pro | C134: ATHLETIC PRO TOP | D134: 127.9 | E134: 279.9 | F134: =D134/4.75 -> 26.926316
A135: 85097 | B135: Legging Athletic Pro | C135: ATHLETIC PRO LEGGING | D135: 104.9 | E135: 229.9 | F135: =D135/4.75 -> 22.084211
A136: 85098 | B136: Jaqueta Dryside | C136: DRYSIDE JACKET | D136: 227.9 | E136: 499.9 | F136: =D136/4.75 -> 47.978947
A137: 85099 | B137: Shorts Dryside | C137: DRYSIDE SHORTS | D137: 158.9 | E137: 349.9 | F137: =D137/4.75 -> 33.452632
A138: 85058 | B138: Blusão Soft Pure | C138: SOFT PURE JACKET | D138: 158.9 | E138: 349.9 | F138: =D138/4.75 -> 33.452632
A139: 85059 | B139: Calca Soft Pure | C139: SOFT PURE PANTS | D139: 190.9 | E139: 419.9 | F139: =D139/4.75 -> 40.189474
A140: 85057 | B140: Vestido Soft Pure | C140: SOFT PURE DRESS | D140: 272.9 | E140: 599.9 | F140: =D140/4.75 -> 57.452632
A141: F2776 | B141: Top Seamless | C141: SEAMLESS TOP | D141: 127.9 | E141: 279.9 | F141: =D141/4.75 -> 26.926316
A142: IP054 | B142: Saia Importado | C142: AERO VISION SKIRT | D142: 158.9 | E142: 349.9 | F142: =D142/4.75 -> 33.452632
A143: IP053 | B143: Jaqueta Nylon Racer | C143: NYLON RACER JACKET | D143: 249.9 | E143: 549.9 | F143: =D143/4.75 -> 52.610526
A144: I4117 | B144: Jaqueta Importado | C144: AERO VISION JACKET | D144: 272.9 | E144: 599.9 | F144: =D144/4.75 -> 57.452632
A145: I4111 | B145: Shorts Importado | C145: SHORTS | D145: 158.9 | E145: 349.9 | F145: =D145/4.75 -> 33.452632
A146: F2777 | B146: Shorts Seamless | C146: SEAMLESS SHORTS | D146: 89.9 | E146: 199.9 | F146: =D146/4.75 -> 18.926316
A147: F2780 | B147: Macaquinho Seamless | C147: SEAMLESS JUMPSUIT | D147: 181.9 | E147: 399.9 | F147: =D147/4.75 -> 38.294737
A148: F2778 | B148: Fusô Seamless | C148: SEAMLESS LEGGING | D148: 127.9 | E148: 279.9 | F148: =D148/4.75 -> 26.926316
A149: 85109 | B149: Top Hydefit | C149: HYDEFIT TOP | D149: 136.9 | E149: 299.9 | F149: =D149/4.75 -> 28.821053
A150: 85110 | B150: Shorts Hydefit | C150: HYDEFIT SHORTS | D150: 89.9 | E150: 199.9 | F150: =D150/4.75 -> 18.926316
A151: 85125 | B151: Legging Hydefit | C151: HYDEFIT LEGGING | D151: 127.9 | E151: 279.9 | F151: =D151/4.75 -> 26.926316
A152: 85106 | B152: Regata New Ribbed Knit | C152: NEW RIBBED KNIT TANK TOP | D152: 68.9 | E152: 149.9 | F152: =D152/4.75 -> 14.505263
A153: 85105 | B153: Camiseta New Ribbed Knit | C153: NEW RIBBED KNIT T-SHIRT | D153: 72.9 | E153: 159.9 | F153: =D153/4.75 -> 15.347368
A154: 85104 | B154: Camiseta New Ribbed Knit | C154: NEW RIBBED KNIT T-SHIRT | D154: 77.9 | E154: 169.9 | F154: =D154/4.75 -> 16.4
...

Sheet ALIVE
A1: Referência | B1: Descrição | C1: Tradução | D1: Sell In | E1: Sell Out | F1: Dólar
A2: 46000 | B2: Cinto Seamless | C2: SEAMLESS BELT | D2: 45.9 | E2: 99.9 | F2: =D2/4.5 -> 10.2
A3: 46001 | B3: Blusa Raglan Seamless | C3: SEAMLESS RAGLAN BLOUSE | D3: 89.9 | E3: 199.9 | F3: =D3/4.5 -> 19.977778
A4: 46003 | B4: Camiseta Seamless | C4: SEAMLESS T-SHIRT | D4: 72.9 | E4: 159.9 | F4: =D4/4.5 -> 16.2
A5: 46004 | B5: Regata Seamless Men | C5: MEN SEAMLESS TANK TOP | D5: 68.9 | E5: 149.9 | F5: =D5/4.5 -> 15.311111
A6: 46005 | B6: Blusão | C6: BLOUSE | D6: 204.9 | E6: 449.9 | F6: =D6/4.5 -> 45.533333
A7: 46006 | B7: Calça | C7: PANTS | D7: 227.9 | E7: 499.9 | F7: =D7/4.5 -> 50.644444
A8: 46007 | B8: Bermuda Move | C8: MOVE SHORT | D8: 159.9 | E8: 349.9 | F8: =D8/4.5 -> 35.533333
A9: 46008 | B9: Camiseta | C9: T-SHIRT | D9: 80.9 | E9: 179.9 | F9: =D9/4.5 -> 17.977778
A10: 46009 | B10: Faixa de Cabelo Seamless | C10: SEAMLESS HAIR BAND | D10: 36.9 | E10: 79.9 | F10: =D10/4.5 -> 8.2
A11: 46010 | B11: Camiseta Comfy Flame LIVE! Men | C11: LIVE! MEN COMFY FLAME T-SHIRT | D11: 72.9 | E11: 159.9 | F11: =D11/4.5 -> 16.2
A12: 46011 | B12: Camiseta Comfy Connect Men | C12: MEN COMFY CONNECT T-SHIRT | D12: 72.9 | E12: 159.9 | F12: =D12/4.5 -> 16.2
A13: 46012 | B13: Camiseta Comfy Lines Men | C13: MEN COMFY LINES T-SHIRT | D13: 72.9 | E13: 159.9 | F13: =D13/4.5 -> 16.2
... A168: 46204 | B168: Blusa Ribbed Knit Kids | C168: KIDS RIBBER KNIT BLOUSE | D168: 54.9 | E168: 119.9 | F168: =D168/4.5 -> 12.2
A169: F2216 | B169: Meia Sapatilha Invisible | C169: INVISIBLE SOCK | D169: 26.9 | E169: 69.9 | F169: =D169/4.5 -> 5.9777778
A170: F2222 | B170: Kit Meias Workout | C170: KIT WORKOUT SOCKS | D170: 45.9 | E170: 109.9 | F170: =D170/4.5 -> 10.2
A171: F2758 | B171: Sunga Men Acqua | C171: MEN ACQUA TRUNK | D171: 81.9 | E171: 179.9 | F171: =D171/4.5 -> 18.2
A172: F2759 | B172: Bermuda Men Acqua | C172: MEN ACQUA SHORT | D172: 89.9 | E172: 199.9 | F172: =D172/4.5 -> 19.977778
A173: F2760 | B173: Maiô Acqua | C173: ACQUA SWIMSUIT | D173: 127.9 | E173: 279.9 | F173: =D173/4.5 -> 28.422222
A174: F2762 | B174: Top Explore Seamless Knit® | C174: EXPLORE SEAMLESS KNIT TOP | D174: 89.9 | E174: 199.9 | F174: =D174/4.5 -> 19.977778
A175: F2763 | B175: Legging Explore Seamless Knit® | C175: EXPLORE SEAMLESS KNIT LEGGING | D175: 136.9 | E175: 299.9 | F175: =D175/4.5 -> 30.422222
A176: F2764 | B176: Macacão Shorts Seamless Knit® | C176: SEAMLESS KNIT SHORT JUMPSUIT | D176: 136.9 | E176: 299.9 | F176: =D176/4.5 -> 30.422222
A177: F2765 | B177: Top V Rib Classic Seamless | C177: RIBE CLASSIC SEAMLESS V TOP | D177: 89.9 | E177: 199.9 | F177: =D177/4.5 -> 19.977778
A178: F2769 | B178: Legging Rib Classic Seamless | C178: RIB CLASSIC SEAMLESS LEGGING | D178: 113.9 | E178: 249.9 | F178: =D178/4.5 -> 25.311111
A179: F2770 | B179: Shorts Rib Classic Seamless | C179: RIB CLASSIC SEAMLESS SHORT | D179: 81.9 | E179: 179.9 | F179: =D179/4.5 -> 18.2
A180: F2771 | B180: Regata | C180: TANK TOP | D180: 68.9 | E180: 149.9 | F180: =D180/4.5 -> 15.311111
... A321: P1254 | B321: Legging Icon Neo Kids | C321: KIDS ICON NEO LEGGING | D321: 77.9 | E321: 169.9 | F321: =D321/4.5 -> 17.311111
A322: P1265 | B322: Bolsa Live! Everyday | C322: LIVE! EVERYDAY BAG | D322: 33.9 | E322: BOLSA PARA VENDEDORAS LOJA | F322: =D322/4.5 -> 7.5333333
A323: P1267 | B323: Top Wide | C323: WIDE TOP | D323: 99.9 | E323: 219.9 | F323: =D323/4.5 -> 22.2
A324: P1268 | B324: Vestido Fit Hydefit® Adaptiv | C324: HYDEFIT ADAPTIV FIT DRESS | D324: 168.9 | E324: 369.9 | F324: =D324/4.5 -> 37.533333
A325: P1270 | B325: Calça Flare Allure® Adaptiv | C325: ALLURE ADAPTIV PANTS | D325: 145.9 | E325: 319.9 | F325: =D325/4.5 -> 32.422222
A326: P1272 | B326: Shorts Fit Icon Neo Reflex | C326: ICON NEO REFLEX FIT SHORT | D326: 99.9 | E326: 219.9 | F326: =D326/4.5 -> 22.2
A327: P1273 | B327: Calça Fusô Icon Neo Reflex | C327: ICON NEO REFLEX PANTS | D327: 135.9 | E327: 299.9 | F327: =D327/4.5 -> 30.2
A328: P1275 | B328: Camiseta Icon Reflex Comfort | C328: ICON REFLEX COMFORT T-SHIRT | D328: 81.9 | E328: 179.9 | F328: =D328/4.5 -> 18.2
A329: P1277 | B329: Regata Cropped LIVE! Reflex | C329: LIVE! REFLEX CROPPED TANK TOP | D329: 72.9 | E329: 159.9 | F329: =D329/4.5 -> 16.2
A330: P1279 | B330: Camiseta ML Thermo Skin | C330: THERMO SKIN T-SHIRT | D330: 99.9 | E330: 219.9 | F330: =D330/4.5 -> 22.2
A331: P1280 | B331: Legging Sense Pro Fleece | C331: SENSE PRO FLEECE LEGGING | D331: 99.9 | E331: 219.9 | F331: =D331/4.5 -> 22.2
A332: P1281 | B332: Regata Comfy Bio Stretch Men | C332: MEN COMFY BIO STRETCH TANK TOP | D332: 89.9 | E332: 199.9 | F332: =D332/4.5 -> 19.977778
A333: P1282 | B333: Shorts Run 3'' Dryside Men | C333: MEN RUN 3 DRYSIDE SHORT | D333: 113.9 | E333: 249.9 | F333: =D333/4.5 -> 25.311111
A334: P1285 | B334: Bermuda Pro 5'' Dryside | C334: PRO 5 DRYSIDE SHORT | D334: 127.9 | E334: 279.9 | F334: =D334/4.5 -> 28.422222
...

Sheet DREAMERS
A1: Referência | B1: Descrição | C1: Description | D1: Sell In | E1: Dolar
A2: 84758 | B2: TOP GROOVE LINE | C2: GROOVE LINE TOP | D2: 113.9 | E2: 25.311111
A3: 84759 | B3: SHORTS GROOVE LINE | C3: GROOVE LINE SHORT | D3: 89.9 | E3: 19.977778
A4: 84760 | B4: LEGGING GROOVE LINE | C4: GROOVE LINE LEGGING | D4: 145.9 | E4: 32.422222
A5: 84761 | B5: MACACAO GROOVE LINE | C5: GROOVE LINE JUMPSUIT | D5: 149.9 | E5: 33.311111
A6: 84762 | B6: CAMISETA CROPPED WIDE | C6: WIDE CROPPED T-SHIRT | D6: 68.9 | E6: 15.311111
A7: 84765 | B7: TOP DYNAMIC MAT | C7: DYNAMIC MAT TOP | D7: 113.9 | E7: 25.311111
A8: 84766 | B8: SHORTS DYNAMIC MAT | C8: DYNAMIC MAT SHORT | D8: 89.9 | E8: 19.977778
A9: 84767 | B9: LEGGING DYNAMIC MAT | C9: DYNAMIC MAT LEGGING | D9: 127.9 | E9: 28.422222
A10: 84770 | B10: REGATA WIDE | C10: WIDE TANK TOP | D10: 68.9 | E10: 15.311111
A11: 84772 | B11: CAMISETA COMFY MOVIMENT MEN | C11: MEN COMFY MOVIMENT T-SHIRT | D11: 72.9 | E11: 16.2
A12: 84773 | B12: CAMISETA COMFY STRIPE MEN | C12: MEN COMFY STRIPE T-SHIRT | D12: 72.9 | E12: 16.2
A13: 84774 | B13: CAMISETA COMFY HYPER MEN | C13: MEN COMFY HYPER T-SHIRT | D13: 72.9 | E13: 16.2
... A133: 84939 | B133: CALCA JOG EVERYDAY | C133: JOG EVERYDAY PANTS | D133: 172.9 | E133: 38.422222
A134: 84942 | B134: TOP SENSE FLEECE | C134: SENSE FLEECE TOP | D134: 109.9 | E134: 24.422222 | F134: =D134*0.4 -> 43.96
A135: 84943 | B135: FUSO SENSE FLEECE | C135: SENSE FLEECE LEGGING | D135: 127.9 | E135: 28.422222
A136: 84945 | B136: BERMUDA LIFT | C136: LIFT SHORT | D136: 113.9 | E136: 25.311111
A137: 84946 | B137: LEGGING LIFT | C137: LIFT LEGGING | D137: 127.9 | E137: 28.422222
A138: 84947 | B138: BLUSAO FROSTY | C138: FROSTY BLOUSE | D138: 159.9 | E138: 35.533333
A139: 84972 | B139: REGATA WIDE KIDS | C139: KIDS WIDE TANK TOP | D139: 54.9 | E139: 12.2
A140: 84973 | B140: CAMISETA WIDE KIDS | C140: KIDS WIDE T-SHIRT | D140: 59.9 | E140: 13.311111
A141: 84974 | B141: CAMISETA RIBBED KIDS | C141: KID RIBBED T-SHIRT | D141: 59.9 | E141: 13.311111
A142: 84975 | B142: LEGGING KIDS | C142: KIDS LEGGING | D142: 87.9 | E142: 19.533333
A143: 84976 | B143: LEGGING MAT KIDS | C143: KIDS MAT LEGGING | D143: 68.9 | E143: 15.311111
A144: 84977 | B144: JAQUETA FLEECE KIDS | C144: KIDS FLEECE JACKET | D144: 136.9 | E144: 30.422222
A145: 84978 | B145: CALCA FLEECE KIDS | C145: KIDS FLEECE PANTS | D145: 104.9 | E145: 23.311111
A146: 84979 | B146: JAQUETA JOG KIDS | C146: KIDS JOG JACKET | D146: 159.9 | E146: 35.533333
... A155: 84989 | B155: BERMUDA MOVE STREET MEN | C155: MEN MOVE STREET SHORT | D155: 136.9 | E155: 30.422222
A156: F2216 | B156: MEIA SAPATILHA INVISIBLE | C156: INVISIBLE ANKLE SOCKS | D156: 26.9 | E156: 5.9777778
A157: F2222 | B157: KIT MEIAS STRIDE | C157: STRIDE SOCKS KIT | D157: 45.9 | E157: 10.2
A158: F2369 | B158: REGATA FLOW | C158: FLOW TANK TOP | D158: 68.9 | E158: 15.311111
A159: F2435 | B159: CAMISETA ML FLOW | C159: FLOW T-SHIRT | D159: 89.9 | E159: 19.977778
A160: F2437 | B160: REGATA LONG FLOW | C160: LONG FLOW TANK TOP | D160: 63.9 | E160: 14.2
A161: F2662 | B161: TOP STRIPE SEAMLESS | C161: STRIPE SEAMLESS TOP | D161: 86.9 | E161: 19.311111
A162: F2666 | B162: FUSO STRIPE SEAMLESS | C162: STRIPE SEAMLESS LEGGING | D162: 89.9 | E162: 19.977778
A163: F2722 | B163: TOP CONTOUR SEAMLESS | C163: CONTOUR SEAMLESS TOP | D163: 89.9 | E163: 19.977778
A164: F2723 | B164: LEGGING CONTOUR SEAMLESS | C164: CONTOUR SEAMLESS LEGGING | D164: 89.9 | E164: 19.977778
A165: F2743 | B165: TOP DYNAMIC SEAMLESS | C165: DYNAMIC SEAMLESS TOP | D165: 89.9 | E165: 19.977778
A166: F2744 | B166: LEGGING DYNAMIC SEAMLESS | C166: DYNAMIC SEAMLESS LEGGING | D166: 113.9 | E166: 25.311111
A167: F2745 | B167: TOP STRIPE SEAMLESS | C167: STRIPE SEAMLESS TOP | D167: 81.9 | E167: 18.2
...

Sheet Plan6
A1: NCM | B1: HS CODE | C1: Imposto | D1: Descrição
A2: 3923.30.00 | B2: 3923.30.00.90 | C2: 0.0404 | D2: shaker, squeeze
A3: 4202.22.10 | B3: 4202.22.15.00 | C3: 0.2708
A4: 4202.22.20 | B4: 4202.22.40.40 | C4: 0.0844 | D4: bolsa
A5: 4202.29.00 | B5: 4202.29.50.00 | C5: 0.0884 | D5: bolsa
A6: 4202.92.00 | B6: 4202.92.08.05 | C6: 0.0804
A7: 4202.92.00 | B7: 4202.92.08.07 | C7: 0.0804
A8: 4202.92.00 | B8: 4202.92.08.09 | C8: 0.0804
A9: 4202.99.00 | B9: 4202.99.50.00 | C9: 0.0884
A10: 4911.91.00 | B10: 4911.91.20.40 | C10: 0.0104 | D10: Catálogo, mini revista
A11: 6101.20.00 | B11: 6101.20.00.10 | C11: 0.1696
A12: 6101.30.00 | B12: 6101.30.20.10 | C12: 0.2924
A13: 6102.20.00 | B13: 6102.20.00.10 | C13: 0.1696 | D13: Casaco, kaftan
A14: 6102.30.00 | B14: 6102.30.20.10 | C14: 0.2924 | D14: jaqueta, casaco
A15: 6103.42.00 | B15: 6103.42.10.50 | C15: 0.1716 | D15: legging, shorts, fuso, bermuda, capri
A16: 6103.43.00 | B16: 6103.43.10.20 | C16: 0.1595 | D16: legging, shorts, fuso, bermuda, capri
A17: 6104.29.90 | B17: 6104.29.05.40 | C17: 0.0104
A18: 6104.42.00 | B18: 6104.42.00.10 | C18: 0.1256
A19: 6104.43.00 | B19: 6104.43.10.10 | C19: 0.1594 | D19: saída de praia
A20: 6104.44.00 | B20: 6104.44.20.10 | C20: 0.1594
A21: 6104.52.00 | B21: 6104.52.00.10 | C21: 0.0936
A22: 6104.53.00 | B22: 6104.53.10.00 | C22: 0.1594 | D22: shorts, vestido, saída de praia, saia shorts
A23: 6104.62.00 | B23: 6104.62.10.20 | C23: 0.1136
A24: 6104.63.00 | B24: 6104.63.10.20 | C24: 0.1595 | D24: legging, shorts, fuso, bermuda, capri
A25: 6105.20.00 | B25: 6105.20.10.00 | C25: 0.3305 | D25: blusa, regata
A26: 6106.10.00 | B26: 6106.10.00.10 | C26: 0.2076 | D26: blusa, regata
A27: 6106.20.00 | B27: 6106.20.10.10 | C27: 0.1594 | D27: Blusa, regata, casaco,
A28: 6109.10.00 | B28: 6109.10.00.70 | C28: 0.1756
A29: 6109.90.00 | B29: 6109.90.80.10 | C29: 0.1705 | D29: casual
A30: 6110.20.00 | B30: 6110.20.10.10 | C30: 0.0605
A31: 6110.20.00 | B31: 6110.20.10.20 | C31: 0.0606
A32: 6110.30.00 | B32: 6110.30.10.40 | C32: 0.0704 | D32: Colete
A33: 6112.12.00 | B33: 6112.12.00.20 | C33: 0.282 | D33: Shorts
A34: 6112.31.00 | B34: 6112.31.00.10 | C34: 0.2695 | D34: sunga
A35: 6112.41.00 | B35: 6112.41.00.10 | C35: 0.2595 | D35: top e tanga de biquini, maiô,
A36: 6114.20.00 | B36: 6114.20.00.10 | C36: 0.1186
A37: 6114.30.00 | B37: 6114.30.30.30 | C37: 0.1595 | D37: top, blusa
A38: 6115.95.00 | B38: 6115.95.90.00 | C38: 0.1456 | D38: meia
A39: 6116.93.00 | B39: 6116.93.08.00 | C39: 0.0384 | D39: luvas
A40: 6117.10.00 | B40: 6117.10.20.30 | C40: 12,34%%
...
